Workbook

Sheet Client Report
H2: High Level Grid Tied Solar Feasibility
B4: Building Name | D4: Black chain,Katutura | F4: Region | G4: =Inputs!B23
B5: Building Address | D5: Street, City | F5: Connection Type | G5: EL40
B6: Building type
B7: Gross Lettable Area
B8: Roof Space Available
H9: Overview
E10: Current (Grid) | F10: Solar PV Lease | G10: Solar PV Buy (Outright) | H10: Solar PV Buy (Green Loan)
B11: Levelized cost of Energy | E11: =Inputs!B15 | F11: =Inputs!B16 | G11: ='Cash Flow'!E25/'Cash Flow'!B24 | H11: =(5*E23+'Cash Flow'!E24)/'Cash Flow'!B24
B12: Total Saving per annum (levelized) | F12: =Dashboard!B8*('Client Report'!E11-'Client Report'!F11) | G12: =Dashboard!B8*('Client Report'!E11-'Client Report'!G11) | H12: =Dashboard!B8*('Client Report'!E11-'Client Report'!H11)
B13: Total Saving over 20 year project period | F13: =SUM('Cash Flow'!D4:D23)-'Cash Flow'!D50 | G13: ='Cash Flow'!F24 | H13: ='Cash Flow'!I23+Dashboard!B22-5*E23
B14: Internal Rate of Return on Investment | G14: =Dashboard!B19
B16: Total Annual Energy cost (N$)
B17: Cost of Energy from grid (Annual N$) | H17: =Inputs!B15*Dashboard!B8
B18: Cost of Energy from Solar (Annual N$) | E18: 0 | H18: =H11*Dashboard!B8
H20: PV System
B22: Total PV system cost including consulting fees (N$)
B23: Green loan repayment (N$ per annum) | E23: =(Dashboard!B22*'Client Report'!G24)/'Client Report'!D24
B24: Green loan terms | D24: 5 | E24: years | G24: 1.105 | H24: % interest
C27: Graph cumulative savings
G41: Outright Purchase

Sheet Dashboard
A1: Solar PV Feasibility Dashboard
A3: Metric | B3: Value | C3: Unit | D3: Basis
A4: Selected region | B4: =Inputs!B23 | D4: Dropdown on Inputs sheet
A5: Regional kWh/kWp/year used | B5: =Inputs!B14 | C5: kWh/kWp/year | D5: Auto pulled from Region Yields sheet
A6: Model PV size | B6: =Inputs!B31 | C6: kWp | D6: Minimum of desired, breaker and roof limit
A7: No. of panels | B7: =Inputs!B32 | C7: panels | D7: Default setup gives 703 panels
A8: Year 1 energy (kWh) | B8: =Inputs!B34 | C8: kWh | D8: PV size × selected region yield
A9: Roof area required (m²) | B9: =Inputs!B35 | C9: m² | D9: Panels × panel area ÷ roof factor
A10: Area needed | B10: =Inputs!B35 | C10: m² | D10: Same as roof area required
A11: Year 1 cost of energy from grid | B11: =Inputs!B36 | C11: NAD | D11: Year 1 energy × grid tariff
A12: Year 1 cost of energy from solar | B12: =Inputs!B38 | C12: NAD | D12: Year 1 energy × calculated solar LCOE
A13: Year 1 gross savings (NAD) | B13: =Inputs!B39 | C13: NAD | D13: Avoided grid cost before O&M
A14: Year 1 O&M (NAD) | B14: =Inputs!B40 | C14: NAD | D14: 1% of capital cost by default
A15: Year 1 net savings (NAD) | B15: =Inputs!B41 | C15: NAD | D15: Gross savings minus O&M
A16: Cost from grid | B16: =Inputs!B15 | C16: NAD/kWh | D16: Current grid tariff
A17: Cost of energy from solar | B17: ='Cash Flow'!L6 | C17: NAD/kWh | D17: Calculated discounted LCOE
A18: Tariff less solar LCOE | B18: ='Cash Flow'!L8 | C18: NAD/kWh | D18: Positive means solar is cheaper per kWh
A19: IRR | B19: ='Cash Flow'!L4 | C19: % | D19: Internal rate of return based on year 0 to year 20 net cash flow
A20: Payback year | B20: ='Cash Flow'!L5 | C20: year | D20: First year cumulative cash flow becomes positive
A21: NPV | B21: ='Cash Flow'!L3 | C21: NAD | D21: Discounted net cash flow
A22: Capital cost | B22: =Inputs!B33 | C22: NAD | D22: PV size × installed cost
A26: Tariff vs LCOE Sensitivity
A27: Scenario | B27: Grid tariff | C27: Solar LCOE | D27: Year 1 benefit
A28: =Sensitivity!A16 | B28: =Inputs!B15 | C28: =Sensitivity!C16 | D28: =Sensitivity!F16
A29: =Sensitivity!A17 | B29: =Sensitivity!B17 | C29: =Sensitivity!C17 | D29: =Sensitivity!F17
A30: =Sensitivity!A18 | B30: =Sensitivity!B18 | C30: =Sensitivity!C18 | D30: =Sensitivity!F18
A31: =Sensitivity!A19 | B31: =Sensitivity!B19 | C31: =Sensitivity!C19 | D31: =Sensitivity!F19
A32: =Sensitivity!A20 | B32: =Sensitivity!B20 | C32: =Sensitivity!C20 | D32: =Sensitivity!F20

Sheet Inputs
A1: Solar PV Feasibility Study Inputs
A2: ConnectionType | B2: ='Client Report'!G5
A3: Location | B3: ='Client Report'!D4
A4: Input | B4: Value | C4: Unit | D4: Note
A5: Main breaker rating | B5: 1000 | C5: A | D5: Editable
A6: System voltage | B6: 400 | C6: V | D6: Use 400 V for 3-phase. Use 230 V for single-phase.
A7: Power factor | B7: 0.9 | D7: Editable
A8: Margin | B8: 0.2 | D8: Editable design margin deducted from breaker capacity
A9: Desired PV size | B9: 350 | C9: kWp | D9: Default gives 703 panels with 550 W panels
A10: Panel power | B10: 550 | C10: W | D10: Editable panel/module rating
A11: Area available | B11: 3000 | C11: m² | D11: Editable available roof/ground area
A12: Panel area | B12: 2.6 | C12: m²/panel | D12: Editable panel area
A13: Roof factor | B13: 0.75 | D13: Allowance for setbacks, access ways and unusable roof area
A14: Specific yield | B14: =INDEX('Region Yields'!$B$3:$B$6,MATCH($B$23,'Region Yields'!$A$3:$A$6,0)) | C14: kWh/kWp/year | D14: Auto-populates from selected region
A15: Grid Tariff | B15: 2.367 | C15: NAD/kWh | D15: Editable current grid energy tariff
A16: Lease/PPA tariff | B16: 1.749 | C16: NAD/kWh | D16: Editable lease/PPA tariff (linked to Cash Flow lease model)
A17: Tariff escalation | B17: 0.03 | D17: Editable. 0.03 = 3% per year
A18: Installed cost | B18: 9500 | C18: NAD/kWp | D18: Editable installed cost
A19: O&M | B19: 0.01 | C19: of capital cost/year | D19: Editable. 0.01 = 1% of capital cost
A20: PV degradation | B20: 0.005 | D20: Editable. 0.005 = 0.5% per year (SANS 10400-XA)
A21: Project life | B21: 20 | C21: years | D21: Editable project period
A22: Discount rate | B22: 0.1 | D22: Editable discount rate
A23: Region | B23: South | D23: Dropdown: Coastal, North, South, Central
A27: Calculated Values
A28: Calculation | B28: Value | C28: Unit | D28: Formula basis
A29: Max PV from breaker | B29: =IF(B6>250,SQRT(3)*B5*B6*B7*(1-B8)/1000,B5*B6*B7*(1-B8)/1000) | C29: kWp | D29: Breaker capacity limit
A30: Max PV from roof | B30: =(B11*B13/B12)*B10/1000 | C30: kWp | D30: Area available × roof factor ÷ panel area × panel power
A31: Model PV size | B31: =MIN(B9,B29,B30) | C31: kWp | D31: Minimum of desired PV, breaker limit and roof limit
A32: No. of panels | B32: =ROUNDUP(B31*1000/B10,0) | C32: panels | D32: Model PV size ÷ panel power
A33: Capital cost | B33: =B31*B18 | C33: NAD | D33: Model PV size × installed cost
A34: Year 1 energy | B34: =B31*B14 | C34: kWh | D34: Model PV size × selected regional specific yield
A35: Roof area required | B35: =B32*B12/B13 | C35: m² | D35: No. panels × panel area ÷ roof factor
A36: Year 1 grid energy cost | B36: =B34*B15 | C36: NAD | D36: Year 1 energy × grid tariff
A37: Calculated solar LCOE | B37: ='Cash Flow'!L6 | C37: NAD/kWh | D37: Capital + discounted O&M divided by discounted kWh
A38: Year 1 solar energy cost | B38: =B34*B37 | C38: NAD | D38: Year 1 energy × calculated solar LCOE
A39: Year 1 gross savings | B39: =B36 | C39: NAD | D39: Avoided grid cost before O&M
A40: Year 1 O&M | B40: =B33*B19 | C40: NAD | D40: Capital cost × O&M %
A41: Year 1 net savings | B41: =B39-B40 | C41: NAD | D41: Gross savings minus O&M
A42: Tariff less solar LCOE | B42: =B15-B37 | C42: NAD/kWh | D42: Grid tariff minus calculated solar LCOE

Sheet Cash Flow
A1: Cash Flow with Annual kWh Production and Levelised Solar Cost
A2: Year | B2: Production kWh | C2: Grid tariff NAD/kWh | D2: Grid energy cost NAD | E2: O&M NAD | F2: Net cash flow NAD | G2: Discount factor | H2: Discounted net cash flow NAD | I2: Cumulative cash flow NAD | J2: Discounted energy kWh | K2: Summary | L2: Value
A3: 0 | B3: 0 | C3: 0 | D3: 0 | E3: 0 | F3: =-Inputs!B33 | G3: =1 | H3: =F3*G3 | I3: =F3 | J3: 0 | K3: NPV of net cash flow | L3: =SUM(H3:H23)
A4: 1 | B4: =IF(A4>Inputs!B21,0,Inputs!B31*Inputs!B14*(1-Inputs!B20)^(A4-1)) | C4: =IF(A4>Inputs!B21,0,Inputs!B15*(1+Inputs!B17)^(A4-1)) | D4: =B4*C4 | E4: =IF(A4>Inputs!B21,0,Inputs!B33*Inputs!B19*(1+Inputs!B17)^(A4-1)) | F4: =D4-E4 | G4: =IF(A4>Inputs!B21,0,1/(1+Inputs!B22)^A4) | H4: =F4*G4 | I4: =I3+F4 | J4: =B4*G4 | K4: IRR | L4: =IFERROR(IRR(F3:F23),"No IRR")
A5: 2 | B5: =IF(A5>Inputs!B21,0,Inputs!B31*Inputs!B14*(1-Inputs!B20)^(A5-1)) | C5: =IF(A5>Inputs!B21,0,Inputs!B15*(1+Inputs!B17)^(A5-1)) | D5: =B5*C5 | E5: =IF(A5>Inputs!B21,0,Inputs!B33*Inputs!B19*(1+Inputs!B17)^(A5-1)) | F5: =D5-E5 | G5: =IF(A5>Inputs!B21,0,1/(1+Inputs!B22)^A5) | H5: =F5*G5 | I5: =I4+F5 | J5: =B5*G5 | K5: Payback year | L5: =IFERROR(INDEX(A4:A23,MATCH(TRUE,I4:I23>=0,0)),"No payback inside project life")
A6: 3 | B6: =IF(A6>Inputs!B21,0,Inputs!B31*Inputs!B14*(1-Inputs!B20)^(A6-1)) | C6: =IF(A6>Inputs!B21,0,Inputs!B15*(1+Inputs!B17)^(A6-1)) | D6: =B6*C6 | E6: =IF(A6>Inputs!B21,0,Inputs!B33*Inputs!B19*(1+Inputs!B17)^(A6-1)) | F6: =D6-E6 | G6: =IF(A6>Inputs!B21,0,1/(1+Inputs!B22)^A6) | H6: =F6*G6 | I6: =I5+F6 | J6: =B6*G6 | K6: Calculated solar LCOE NAD/kWh | L6: =(Inputs!B33+SUMPRODUCT(E4:E23,G4:G23))/SUM(J4:J23)
A7: 4 | B7: =IF(A7>Inputs!B21,0,Inputs!B31*Inputs!B14*(1-Inputs!B20)^(A7-1)) | C7: =IF(A7>Inputs!B21,0,Inputs!B15*(1+Inputs!B17)^(A7-1)) | D7: =B7*C7 | E7: =IF(A7>Inputs!B21,0,Inputs!B33*Inputs!B19*(1+Inputs!B17)^(A7-1)) | F7: =D7-E7 | G7: =IF(A7>Inputs!B21,0,1/(1+Inputs!B22)^A7) | H7: =F7*G7 | I7: =I6+F7 | J7: =B7*G7 | K7: Grid tariff Year 1 NAD/kWh | L7: =Inputs!B15
A8: 5 | B8: =IF(A8>Inputs!B21,0,Inputs!B31*Inputs!B14*(1-Inputs!B20)^(A8-1)) | C8: =IF(A8>Inputs!B21,0,Inputs!B15*(1+Inputs!B17)^(A8-1)) | D8: =B8*C8 | E8: =IF(A8>Inputs!B21,0,Inputs!B33*Inputs!B19*(1+Inputs!B17)^(A8-1)) | F8: =D8-E8 | G8: =IF(A8>Inputs!B21,0,1/(1+Inputs!B22)^A8) | H8: =F8*G8 | I8: =I7+F8 | J8: =B8*G8 | K8: Tariff less solar LCOE NAD/kWh | L8: =Inputs!B15-L6
A9: 6 | B9: =IF(A9>Inputs!B21,0,Inputs!B31*Inputs!B14*(1-Inputs!B20)^(A9-1)) | C9: =IF(A9>Inputs!B21,0,Inputs!B15*(1+Inputs!B17)^(A9-1)) | D9: =B9*C9 | E9: =IF(A9>Inputs!B21,0,Inputs!B33*Inputs!B19*(1+Inputs!B17)^(A9-1)) | F9: =D9-E9 | G9: =IF(A9>Inputs!B21,0,1/(1+Inputs!B22)^A9) | H9: =F9*G9 | I9: =I8+F9 | J9: =B9*G9 | K9: Year 1 net cash flow | L9: =F4
A10: 7 | B10: =IF(A10>Inputs!B21,0,Inputs!B31*Inputs!B14*(1-Inputs!B20)^(A10-1)) | C10: =IF(A10>Inputs!B21,0,Inputs!B15*(1+Inputs!B17)^(A10-1)) | D10: =B10*C10 | E10: =IF(A10>Inputs!B21,0,Inputs!B33*Inputs!B19*(1+Inputs!B17)^(A10-1)) | F10: =D10-E10 | G10: =IF(A10>Inputs!B21,0,1/(1+Inputs!B22)^A10) | H10: =F10*G10 | I10: =I9+F10 | J10: =B10*G10
A11: 8 | B11: =IF(A11>Inputs!B21,0,Inputs!B31*Inputs!B14*(1-Inputs!B20)^(A11-1)) | C11: =IF(A11>Inputs!B21,0,Inputs!B15*(1+Inputs!B17)^(A11-1)) | D11: =B11*C11 | E11: =IF(A11>Inputs!B21,0,Inputs!B33*Inputs!B19*(1+Inputs!B17)^(A11-1)) | F11: =D11-E11 | G11: =IF(A11>Inputs!B21,0,1/(1+Inputs!B22)^A11) | H11: =F11*G11 | I11: =I10+F11 | J11: =B11*G11
A12: 9 | B12: =IF(A12>Inputs!B21,0,Inputs!B31*Inputs!B14*(1-Inputs!B20)^(A12-1)) | C12: =IF(A12>Inputs!B21,0,Inputs!B15*(1+Inputs!B17)^(A12-1)) | D12: =B12*C12 | E12: =IF(A12>Inputs!B21,0,Inputs!B33*Inputs!B19*(1+Inputs!B17)^(A12-1)) | F12: =D12-E12 | G12: =IF(A12>Inputs!B21,0,1/(1+Inputs!B22)^A12) | H12: =F12*G12 | I12: =I11+F12 | J12: =B12*G12
A13: 10 | B13: =IF(A13>Inputs!B21,0,Inputs!B31*Inputs!B14*(1-Inputs!B20)^(A13-1)) | C13: =IF(A13>Inputs!B21,0,Inputs!B15*(1+Inputs!B17)^(A13-1)) | D13: =B13*C13 | E13: =IF(A13>Inputs!B21,0,Inputs!B33*Inputs!B19*(1+Inputs!B17)^(A13-1)) | F13: =D13-E13 | G13: =IF(A13>Inputs!B21,0,1/(1+Inputs!B22)^A13) | H13: =F13*G13 | I13: =I12+F13 | J13: =B13*G13
A14: 11 | B14: =IF(A14>Inputs!B21,0,Inputs!B31*Inputs!B14*(1-Inputs!B20)^(A14-1)) | C14: =IF(A14>Inputs!B21,0,Inputs!B15*(1+Inputs!B17)^(A14-1)) | D14: =B14*C14 | E14: =IF(A14>Inputs!B21,0,Inputs!B33*Inputs!B19*(1+Inputs!B17)^(A14-1)) | F14: =D14-E14 | G14: =IF(A14>Inputs!B21,0,1/(1+Inputs!B22)^A14) | H14: =F14*G14 | I14: =I13+F14 | J14: =B14*G14
A15: 12 | B15: =IF(A15>Inputs!B21,0,Inputs!B31*Inputs!B14*(1-Inputs!B20)^(A15-1)) | C15: =IF(A15>Inputs!B21,0,Inputs!B15*(1+Inputs!B17)^(A15-1)) | D15: =B15*C15 | E15: =IF(A15>Inputs!B21,0,Inputs!B33*Inputs!B19*(1+Inputs!B17)^(A15-1)) | F15: =D15-E15 | G15: =IF(A15>Inputs!B21,0,1/(1+Inputs!B22)^A15) | H15: =F15*G15 | I15: =I14+F15 | J15: =B15*G15
A16: 13 | B16: =IF(A16>Inputs!B21,0,Inputs!B31*Inputs!B14*(1-Inputs!B20)^(A16-1)) | C16: =IF(A16>Inputs!B21,0,Inputs!B15*(1+Inputs!B17)^(A16-1)) | D16: =B16*C16 | E16: =IF(A16>Inputs!B21,0,Inputs!B33*Inputs!B19*(1+Inputs!B17)^(A16-1)) | F16: =D16-E16 | G16: =IF(A16>Inputs!B21,0,1/(1+Inputs!B22)^A16) | H16: =F16*G16 | I16: =I15+F16 | J16: =B16*G16
A17: 14 | B17: =IF(A17>Inputs!B21,0,Inputs!B31*Inputs!B14*(1-Inputs!B20)^(A17-1)) | C17: =IF(A17>Inputs!B21,0,Inputs!B15*(1+Inputs!B17)^(A17-1)) | D17: =B17*C17 | E17: =IF(A17>Inputs!B21,0,Inputs!B33*Inputs!B19*(1+Inputs!B17)^(A17-1)) | F17: =D17-E17 | G17: =IF(A17>Inputs!B21,0,1/(1+Inputs!B22)^A17) | H17: =F17*G17 | I17: =I16+F17 | J17: =B17*G17
A18: 15 | B18: =IF(A18>Inputs!B21,0,Inputs!B31*Inputs!B14*(1-Inputs!B20)^(A18-1)) | C18: =IF(A18>Inputs!B21,0,Inputs!B15*(1+Inputs!B17)^(A18-1)) | D18: =B18*C18 | E18: =IF(A18>Inputs!B21,0,Inputs!B33*Inputs!B19*(1+Inputs!B17)^(A18-1)) | F18: =D18-E18 | G18: =IF(A18>Inputs!B21,0,1/(1+Inputs!B22)^A18) | H18: =F18*G18 | I18: =I17+F18 | J18: =B18*G18
A19: 16 | B19: =IF(A19>Inputs!B21,0,Inputs!B31*Inputs!B14*(1-Inputs!B20)^(A19-1)) | C19: =IF(A19>Inputs!B21,0,Inputs!B15*(1+Inputs!B17)^(A19-1)) | D19: =B19*C19 | E19: =IF(A19>Inputs!B21,0,Inputs!B33*Inputs!B19*(1+Inputs!B17)^(A19-1)) | F19: =D19-E19 | G19: =IF(A19>Inputs!B21,0,1/(1+Inputs!B22)^A19) | H19: =F19*G19 | I19: =I18+F19 | J19: =B19*G19
A20: 17 | B20: =IF(A20>Inputs!B21,0,Inputs!B31*Inputs!B14*(1-Inputs!B20)^(A20-1)) | C20: =IF(A20>Inputs!B21,0,Inputs!B15*(1+Inputs!B17)^(A20-1)) | D20: =B20*C20 | E20: =IF(A20>Inputs!B21,0,Inputs!B33*Inputs!B19*(1+Inputs!B17)^(A20-1)) | F20: =D20-E20 | G20: =IF(A20>Inputs!B21,0,1/(1+Inputs!B22)^A20) | H20: =F20*G20 | I20: =I19+F20 | J20: =B20*G20
A21: 18 | B21: =IF(A21>Inputs!B21,0,Inputs!B31*Inputs!B14*(1-Inputs!B20)^(A21-1)) | C21: =IF(A21>Inputs!B21,0,Inputs!B15*(1+Inputs!B17)^(A21-1)) | D21: =B21*C21 | E21: =IF(A21>Inputs!B21,0,Inputs!B33*Inputs!B19*(1+Inputs!B17)^(A21-1)) | F21: =D21-E21 | G21: =IF(A21>Inputs!B21,0,1/(1+Inputs!B22)^A21) | H21: =F21*G21 | I21: =I20+F21 | J21: =B21*G21
A22: 19 | B22: =IF(A22>Inputs!B21,0,Inputs!B31*Inputs!B14*(1-Inputs!B20)^(A22-1)) | C22: =IF(A22>Inputs!B21,0,Inputs!B15*(1+Inputs!B17)^(A22-1)) | D22: =B22*C22 | E22: =IF(A22>Inputs!B21,0,Inputs!B33*Inputs!B19*(1+Inputs!B17)^(A22-1)) | F22: =D22-E22 | G22: =IF(A22>Inputs!B21,0,1/(1+Inputs!B22)^A22) | H22: =F22*G22 | I22: =I21+F22 | J22: =B22*G22
A23: 20 | B23: =IF(A23>Inputs!B21,0,Inputs!B31*Inputs!B14*(1-Inputs!B20)^(A23-1)) | C23: =IF(A23>Inputs!B21,0,Inputs!B15*(1+Inputs!B17)^(A23-1)) | D23: =B23*C23 | E23: =IF(A23>Inputs!B21,0,Inputs!B33*Inputs!B19*(1+Inputs!B17)^(A23-1)) | F23: =D23-E23 | G23: =IF(A23>Inputs!B21,0,1/(1+Inputs!B22)^A23) | H23: =F23*G23 | I23: =I22+F23 | J23: =B23*G23
B24: =SUM(B3:B23) | D24: =SUM(D3:D23) | E24: =SUM(E3:E23) | F24: =SUM(F3:F23)
E25: =E24+Dashboard!B22
A28: Year | B28: Production kWh | C28: Lease Tariff NAD/kWh | D28: Solar energy cost NAD | E28: Production kWh | F28: Outright Purchase NAD/kWh | G28: Solar energy cost NAD
A29: 0 | B29: 0 | E29: 0
A30: 1 | B30: =B4 | C30: =Inputs!B16 | D30: =B30*C30 | E30: =B30 | F30: 0.31 | G30: =E30*F30
A31: 2 | B31: =B5 | C31: =C30*1.03 | D31: =B31*C31 | E31: =B31 | F31: =F30*1.03 | G31: =E31*F31
A32: 3 | B32: =B6 | C32: =C31*1.03 | D32: =B32*C32 | E32: =B32 | F32: =F31*1.03 | G32: =E32*F32
A33: 4 | B33: =B7 | C33: =C32*1.03 | D33: =B33*C33 | E33: =B33 | F33: =F32*1.03 | G33: =E33*F33
A34: 5 | B34: =B8 | C34: =C33*1.03 | D34: =B34*C34 | E34: =B34 | F34: =F33*1.03 | G34: =E34*F34
A35: 6 | B35: =B9 | C35: =C34*1.03 | D35: =B35*C35 | E35: =B35 | F35: =F34*1.03 | G35: =E35*F35
A36: 7 | B36: =B10 | C36: =C35*1.03 | D36: =B36*C36 | E36: =B36 | F36: =F35*1.03 | G36: =E36*F36
A37: 8 | B37: =B11 | C37: =C36*1.03 | D37: =B37*C37 | E37: =B37 | F37: =F36*1.03 | G37: =E37*F37
A38: 9 | B38: =B12 | C38: =C37*1.03 | D38: =B38*C38 | E38: =B38 | F38: =F37*1.03 | G38: =E38*F38
A39: 10 | B39: =B13 | C39: =C38*1.03 | D39: =B39*C39 | E39: =B39 | F39: =F38*1.03 | G39: =E39*F39
A40: 11 | B40: =B14 | C40: =C39*1.03 | D40: =B40*C40 | E40: =B40 | F40: =F39*1.03 | G40: =E40*F40
A41: 12 | B41: =B15 | C41: =C40*1.03 | D41: =B41*C41 | E41: =B41 | F41: =F40*1.03 | G41: =E41*F41
A42: 13 | B42: =B16 | C42: =C41*1.03 | D42: =B42*C42 | E42: =B42 | F42: =F41*1.03 | G42: =E42*F42
...

Sheet Sensitivity
A1: Sensitivity: Tariff vs Solar LCOE
A3: Values show Year 1 benefit: Year 1 energy × (grid tariff - solar LCOE)
A5: Grid tariff / Solar LCOE | B5: 0.8 | C5: 1 | D5: 1.2 | E5: 1.4 | F5: 1.6 | G5: 1.8 | H5: 2
A6: 1.5 | B6: =Inputs!$B$34*($A6-B$5) | C6: =Inputs!$B$34*($A6-C$5) | D6: =Inputs!$B$34*($A6-D$5) | E6: =Inputs!$B$34*($A6-E$5) | F6: =Inputs!$B$34*($A6-F$5) | G6: =Inputs!$B$34*($A6-G$5) | H6: =Inputs!$B$34*($A6-H$5)
A7: 2 | B7: =Inputs!$B$34*($A7-B$5) | C7: =Inputs!$B$34*($A7-C$5) | D7: =Inputs!$B$34*($A7-D$5) | E7: =Inputs!$B$34*($A7-E$5) | F7: =Inputs!$B$34*($A7-F$5) | G7: =Inputs!$B$34*($A7-G$5) | H7: =Inputs!$B$34*($A7-H$5)
A8: 2.5 | B8: =Inputs!$B$34*($A8-B$5) | C8: =Inputs!$B$34*($A8-C$5) | D8: =Inputs!$B$34*($A8-D$5) | E8: =Inputs!$B$34*($A8-E$5) | F8: =Inputs!$B$34*($A8-F$5) | G8: =Inputs!$B$34*($A8-G$5) | H8: =Inputs!$B$34*($A8-H$5)
A9: 3 | B9: =Inputs!$B$34*($A9-B$5) | C9: =Inputs!$B$34*($A9-C$5) | D9: =Inputs!$B$34*($A9-D$5) | E9: =Inputs!$B$34*($A9-E$5) | F9: =Inputs!$B$34*($A9-F$5) | G9: =Inputs!$B$34*($A9-G$5) | H9: =Inputs!$B$34*($A9-H$5)
A10: 3.5 | B10: =Inputs!$B$34*($A10-B$5) | C10: =Inputs!$B$34*($A10-C$5) | D10: =Inputs!$B$34*($A10-D$5) | E10: =Inputs!$B$34*($A10-E$5) | F10: =Inputs!$B$34*($A10-F$5) | G10: =Inputs!$B$34*($A10-G$5) | H10: =Inputs!$B$34*($A10-H$5)
A11: 4 | B11: =Inputs!$B$34*($A11-B$5) | C11: =Inputs!$B$34*($A11-C$5) | D11: =Inputs!$B$34*($A11-D$5) | E11: =Inputs!$B$34*($A11-E$5) | F11: =Inputs!$B$34*($A11-F$5) | G11: =Inputs!$B$34*($A11-G$5) | H11: =Inputs!$B$34*($A11-H$5)
A15: Scenario | B15: Grid tariff | C15: Solar LCOE | D15: Difference | E15: Year 1 energy | F15: Year 1 benefit
A16: Current model | B16: =Inputs!B15 | C16: ='Cash Flow'!L6 | D16: =B16-C16 | E16: =Inputs!B34 | F16: =D16*E16
A17: Low grid tariff | B17: 2 | C17: ='Cash Flow'!L6 | D17: =B17-C17 | E17: =Inputs!B34 | F17: =D17*E17
A18: High grid tariff | B18: 3 | C18: ='Cash Flow'!L6 | D18: =B18-C18 | E18: =Inputs!B34 | F18: =D18*E18
A19: Low solar LCOE | B19: =Inputs!B15 | C19: 1 | D19: =B19-C19 | E19: =Inputs!B34 | F19: =D19*E19
A20: High solar LCOE | B20: =Inputs!B15 | C20: 1.8 | D20: =B20-C20 | E20: =Inputs!B34 | F20: =D20*E20
D27: ``

Sheet Region Yields
A1: Region Yield Lookup
A2: Region | B2: Specific yield | C2: Unit
A3: Coastal | B3: 1600 | C3: kWh/kWp/year
A4: North | B4: 1850 | C4: kWh/kWp/year
A5: South | B5: 2000 | C5: kWh/kWp/year
A6: Central | B6: 1900 | C6: kWh/kWp/year
